Workbook
Name acres_per_sqkm: Units!$C$2
Name mi_per_km: Units!$C$4
Name tbl_ownership: Ownership!$A$2:$B$6
Name WatershedName: aggregate_metrics!$B$2
Name sum_hucareasqkm: 'aggregatedata'!$B$2
Name sum_flowlinelengthperennialkm: 'aggregatedata'!$B$3
Name sum_flowlinelengthintermittentkm: 'aggregatedata'!$B$4
Name sum_flowlinelengthephemeralkm: 'aggregatedata'!$B$5
Name sum_flowlinelengthcanalskm: 'aggregatedata'!$B$6
Name sum_flowlinelengthallkm: 'aggregatedata'!$B$7
Name sum_flowlinefeaturecount: 'aggregatedata'!$B$8
Name sum_waterbodyareasqkm: 'aggregatedata'!$B$9
Name sum_waterbodyfeaturecount: 'aggregatedata'!$B$10
Name sum_waterbodylakespondsareasqkm: 'aggregatedata'!$B$11
Name sum_waterbodylakespondsfeaturecount: 'aggregatedata'!$B$12
Name sum_waterbodyreservoirareasqkm: 'aggregatedata'!$B$13
Name sum_waterbodyreservoirfeaturecount: 'aggregatedata'!$B$14
Name sum_waterbodyestuariesareasqkm: 'aggregatedata'!$B$15
Name sum_waterbodyestuariesfeaturecount: 'aggregatedata'!$B$16
Name sum_waterbodyplayaareasqkm: 'aggregatedata'!$B$17
Name sum_waterbodyplayafeaturecount: 'aggregatedata'!$B$18
Name sum_waterbodyswampmarshareasqkm: 'aggregatedata'!$B$19
Name sum_waterbodyswampmarshfeaturecount: 'aggregatedata'!$B$20
Name sum_waterbodyicesnowareasqkm: 'aggregatedata'!$B$21
Name sum_waterbodyicesnowfeaturecount: 'aggregatedata'!$B$22
Name sum_demsum: 'aggregatedata'!$B$23
Name sum_demcount: 'aggregatedata'!$B$24
Name sum_slopesum: 'aggregatedata'!$B$25
Name sum_slopecount: 'aggregatedata'!$B$26
Name sum_precipsum: 'aggregatedata'!$B$27
Name sum_precipcount: 'aggregatedata'!$B$28
Name sum_catchmentlength: 'aggregatedata'!$B$29
Name sum_catchmentarea: 'aggregatedata'!$B$30
Name min_demminimum: 'aggregatedata'!$B$31
Name min_slopeminimum: 'aggregatedata'!$B$32
Name min_precipminimum: 'aggregatedata'!$B$33
Name min_circularityratio: 'aggregatedata'!$B$34
Name min_elongationratio: 'aggregatedata'!$B$35
Name min_formfactor: 'aggregatedata'!$B$36
Name max_demmaximum: 'aggregatedata'!$B$37
Name max_slopemaximum: 'aggregatedata'!$B$38
Name max_precipmaximum: 'aggregatedata'!$B$39
Name countdistinct_huc: 'aggregatedata'!$B$40

Sheet aggregate_metrics
A1: huc | B1: 1601010103
A2: hucName | B2: Yellow Creek
A3: hucStates | B3: UT
A4: hucAreaSqKm | B4: 536.1
A5: hucAreaAcres | B5: 132474.12
A6: flowlineLengthPerennialKm | B6: 295.74787
A7: flowlineLengthIntermittentKm | B7: 75.271068
A8: flowlineLengthEphemeralKm | B8: 491.17478
A9: flowlineLengthCanalsKm | B9: 21.037935
A10: flowlineLengthAllKm | B10: 884.97594
A11: flowlineFeatureCount | B11: 2382
A12: waterbodyAreaSqKm | B12: 2.2852273
A13: waterbodyFeatureCount | B13: 793
A14: waterbodyLakesPondsAreaSqKm | B14: 2.2331292
A15: waterbodyLakesPondsFeatureCount | B15: 788
... A55: drainageDensityAll | B55: 1.6082703

Sheet Expanded Table
A1: fieldname | B1: value | C1: label | E1: formatted | F1: formatted value | G1: value type | H1: raw units
A2: =aggregate_metrics!A1 | B2: =aggregate_metrics!B1 | C2: HUC Code | E2: =B2 | G2: Int | H2: Unitless
A3: =aggregate_metrics!A2 | B3: =aggregate_metrics!B2 | C3: Watershed Name (HUC) | E3: =B3 | G3: Text | H3: Unitless
A4: =aggregate_metrics!A3 | B4: =aggregate_metrics!B3 | C4: State(s) | E4: =B4 | G4: Text | H4: Unitless
A5: =aggregate_metrics!A4 | B5: =aggregate_metrics!B4 | C5: Catchment Area | E5: =B5 | F5: 1 decimal | G5: Float | H5: Area sq km
A6: =aggregate_metrics!A5 | B6: =aggregate_metrics!B5 | C6: Catchment Area (acres) | E6: =B6 | F6: 1 decimal | G6: Float | H6: Area Acres
A8: =aggregate_metrics!A6 | B8: =aggregate_metrics!B6 | C8: Perrenial Stream Length | E8: =B8 | F8: 1 decimal | G8: Float | H8: Length km
A9: =aggregate_metrics!A7 | B9: =aggregate_metrics!B7 | C9: Intermittent Stream Length | E9: =B9 | F9: 1 decimal | G9: Float | H9: Length km
A10: =aggregate_metrics!A8 | B10: =aggregate_metrics!B8 | C10: Ephemeral Stream Length | E10: =B10 | F10: 1 decimal | G10: Float | H10: Length km
A11: =aggregate_metrics!A9 | B11: =aggregate_metrics!B9 | C11: Canal Length | E11: =B11 | F11: 1 decimal | G11: Float | H11: Length km
A12: =aggregate_metrics!A10 | B12: =aggregate_metrics!B10 | C12: Total Stream Length | E12: =B12 | F12: 1 decimal | G12: Float | H12: Length km
A13: =aggregate_metrics!A11 | B13: =aggregate_metrics!B11 | C13: Number of Stream Segments | E13: =B13 | F13: 1 decimal | G13: Int | H13: Unitless
A15: =aggregate_metrics!A12 | B15: =aggregate_metrics!B12 | C15: Total Waterbody | E15: =B15 | G15: Float | H15: Area sq km
A16: =aggregate_metrics!A13 | B16: =aggregate_metrics!B13 | C16: Total count of Waterbodies | E16: =B16 | G16: Int | H16: Unitless
A17: =aggregate_metrics!A14 | B17: =aggregate_metrics!B14 | C17: Lake | E17: =B17 | G17: Float | H17: Area sq km
A18: =aggregate_metrics!A15 | B18: =aggregate_metrics!B15 | C18: Lake count | E18: =B18 | G18: Int | H18: Unitless
A19: =aggregate_metrics!A16 | B19: =aggregate_metrics!B16 | C19: Reservoir | E19: =B19 | G19: Float | H19: Area sq km
A20: =aggregate_metrics!A17 | B20: =aggregate_metrics!B17 | C20: Reservoir count | E20: =B20 | G20: Int | H20: Unitless
A21: =aggregate_metrics!A18 | B21: =aggregate_metrics!B18 | C21: Estuaries | E21: =B21 | G21: Float | H21: Area sq km
A22: =aggregate_metrics!A19 | B22: =aggregate_metrics!B19 | C22: Estuaries count | E22: =B22 | G22: Int | H22: Unitless
A23: =aggregate_metrics!A20 | B23: =aggregate_metrics!B20 | C23: Playa | E23: =B23 | G23: Float | H23: Area sq km
A24: =aggregate_metrics!A21 | B24: =aggregate_metrics!B21 | C24: Playa count | E24: =B24 | G24: Int | H24: Unitless
A25: =aggregate_metrics!A22 | B25: =aggregate_metrics!B22 | C25: Swamp Marsh | E25: =B25 | G25: Float | H25: Area sq km
A26: =aggregate_metrics!A23 | B26: =aggregate_metrics!B23 | C26: Swamp/Marsh count | E26: =B26 | G26: Int | H26: Unitless
... A28: =aggregate_metrics!A25 | B28: =aggregate_metrics!B25 | C28: Ice/Snow count | E28: =B28 | G28: Int | H28: Unitless
A30: =aggregate_metrics!A26 | B30: =aggregate_metrics!B26 | C30: Max Elevation | E30: =B30 | G30: Float
A31: =aggregate_metrics!A27 | B31: =aggregate_metrics!B27 | C31: Min Elevation | E31: =B31 | G31: Float
A32: =aggregate_metrics!A28 | B32: =aggregate_metrics!B28 | E32: =B32 | G32: Float
A33: =aggregate_metrics!A29 | B33: =aggregate_metrics!B29 | E33: =B33 | G33: Float
A34: =aggregate_metrics!A30 | B34: =aggregate_metrics!B30 | C34: Mean Elevation | E34: =B34 | G34: Float
A35: =aggregate_metrics!A31 | B35: =aggregate_metrics!B31 | C35: Relief | E35: =B35 | G35: Float
A37: =aggregate_metrics!A32 | B37: =aggregate_metrics!B32 | C37: Max Slope | E37: =B37 | G37: Float | H37: Angle
A38: =aggregate_metrics!A33 | B38: =aggregate_metrics!B33 | C38: Min Slope | E38: =B38 | G38: Float | H38: Angle
A39: =aggregate_metrics!A34 | B39: =aggregate_metrics!B34 | E39: =B39 | G39: Float | H39: Angle
A40: =aggregate_metrics!A35 | B40: =aggregate_metrics!B35 | E40: =B40 | G40: Float | H40: Unitless
A41: =aggregate_metrics!A36 | B41: =aggregate_metrics!B36 | C41: Mean Slope | E41: =B41 | G41: Float | H41: Angle
A42: =aggregate_metrics!A37 | B42: =aggregate_metrics!B37 | E42: =B42 | G42: Float | H42: Angle
A44: =aggregate_metrics!A38 | B44: =aggregate_metrics!B38 | C44: Max Precipitation | E44: =B44 | G44: Float | H44: length
A45: =aggregate_metrics!A39 | B45: =aggregate_metrics!B39 | C45: Min Precipitation | E45: =B45 | G45: Float | H45: length
A46: =aggregate_metrics!A40 | B46: =aggregate_metrics!B40 | E46: =B46 | G46: Float
...

Sheet Ownership
A1: OwnerCode | B1: AreaSqM
A2: PVT | B2: 5.0218479e+08
A3: ST | B3: 17375745
A4: LG | B4: 2870059
A5: BLM | B5: 13098466
A6: UND | B6: 146790.49

Sheet Units
A1: Conversion | B1: Cell Name | C1: Value
A2: Acres per sq km | B2: acres_per_sqkm | C2: 241.10538
A3: Sq mi per sq km | B3: sqmi_per_sqkm | C3: 0.38610216
A4: mi per km | B4: mi_per_km | C4: 0.621371

Sheet HUC
A1: Formatted Tables (can be separate tabs in *.xlsx or Google Sheet)
B3: HUC Information
B4: ='Expanded Table'!C3 | C4: ='Expanded Table'!B3
B5: ='Expanded Table'!C2 | C5: ='Expanded Table'!E2
B6: ='Expanded Table'!C4 | C6: ='Expanded Table'!E4
B7: ='Expanded Table'!C5 | C7: ='Expanded Table'!E5 | D7: sq km | E7: =C7*247.105 | F7: acres | G7: =C7/2.59 | H7: sq mi
B10: Ownership
B11: ='Expanded Table'!C65 | C11: ='Expanded Table'!E65 | D11: sq km | E11: =C11*247.105 | F11: acres | G11: =C11/2.59 | H11: sq mi | I11: =C11/C$16
B12: ='Expanded Table'!C66 | C12: ='Expanded Table'!E66 | D12: sq km | E12: =C12*247.105 | F12: acres | G12: =C12/2.59 | H12: sq mi | I12: =C12/C$16
B13: ='Expanded Table'!C67 | C13: ='Expanded Table'!E67 | D13: sq km | E13: =C13*247.105 | F13: acres | G13: =C13/2.59 | H13: sq mi | I13: =C13/C$16
B14: ='Expanded Table'!C68 | C14: ='Expanded Table'!E68 | D14: sq km | E14: =C14*247.105 | F14: acres | G14: =C14/2.59 | H14: sq mi | I14: =C14/C$16
B15: ='Expanded Table'!C69 | C15: ='Expanded Table'!E69 | D15: sq km | E15: =C15*247.105 | F15: acres | G15: =C15/2.59 | H15: sq mi | I15: =C15/C$16
B16: TOTAL AREA | C16: =SUM(C11:C15) | D16: sq km | E16: =C16*247.105 | F16: acres | G16: =C16/2.59 | H16: sq mi | I16: =SUM(I11:I15)

Sheet Hydrography
A1: Formatted Tables (can be separate tabs in *.xlsx or Google Sheet)
B3: Hydrographic Network
B4: ='Expanded Table'!C3 | C4: ='Expanded Table'!B3
B5: ='Expanded Table'!C2 | C5: ='Expanded Table'!E2
B6: ='Expanded Table'!C4 | C6: ='Expanded Table'!E4
B7: ='Expanded Table'!C5 | C7: ='Expanded Table'!E5 | D7: sq km | E7: =C7*247.105 | F7: acres | G7: =C7/2.59 | H7: sq mi
C8: Stream Network Distance | G8: Percent of total
B9: ='Expanded Table'!C8 | C9: ='Expanded Table'!E8 | D9: km | E9: =C9*0.621371 | F9: mi | G9: =C9/C$12
B10: Non Perrenial Stream Length | C10: ='Expanded Table'!E9+'Expanded Table'!E10 | D10: km | E10: =C10*0.621371 | F10: mi | G10: =C10/C$12
B11: ='Expanded Table'!C11 | C11: ='Expanded Table'!E11 | D11: km | E11: =C11*0.621371 | F11: mi | G11: =C11/C$12
B12: ='Expanded Table'!C12 | C12: ='Expanded Table'!E12 | D12: km | E12: =C12*0.621371 | F12: mi | G12: =C12/C$12
B13: Total Stream Length (w.o. canals) | C13: =SUM(C9:C10) | D13: km | E13: =C13*0.621371 | F13: mi | G13: =C13/C$12
E14: Average Segment Length
B15: ='Expanded Table'!C13 | C15: ='Expanded Table'!E13 | D15: # | E15: =C12/C15 | F15: km | G15: =E12/C15 | H15: mi
B16: ='Expanded Table'!C14

Sheet Waterbodies
A1: Formatted Tables (can be separate tabs in *.xlsx or Google Sheet)
B3: Waterbodies
B4: ='Expanded Table'!C3 | C4: =WatershedName
B5: ='Expanded Table'!C2 | C5: ='Expanded Table'!E2
C6: sq km | D6: count | E6: % Area | F6: % Count | G6: Avg. sq km | H6: acres | I6: sq mi
B7: ='Expanded Table'!C17 | C7: ='Expanded Table'!B17 | D7: ='Expanded Table'!E18 | E7: =C7/C$13 | F7: =D7/D$13 | G7: =IF(D7>0,C7/D7,0) | H7: =C7*247.105 | I7: =C7*0.386102
B8: ='Expanded Table'!C19 | C8: ='Expanded Table'!E19 | D8: ='Expanded Table'!E20 | E8: =C8/C$13 | F8: =D8/D$13 | G8: =IF(D8>0,C8/D8,0) | H8: =C8*247.105 | I8: =C8*0.386102
B9: ='Expanded Table'!C21 | C9: ='Expanded Table'!E21 | D9: ='Expanded Table'!E22 | E9: =C9/C$13 | F9: =D9/D$13 | G9: =IF(D9>0,C9/D9,0) | H9: =C9*247.105 | I9: =C9*0.386102
B10: ='Expanded Table'!C23 | C10: ='Expanded Table'!E23 | D10: =C10*247.105 | E10: =C10/C$13 | F10: =D10/D$13 | G10: =IF(D10>0,C10/D10,0) | H10: =C10*247.105 | I10: =C10*0.386102
B11: ='Expanded Table'!C25 | C11: ='Expanded Table'!E25 | D11: ='Expanded Table'!E26 | E11: =C11/C$13 | F11: =D11/D$13 | G11: =IF(D11>0,C11/D11,0) | H11: =C11*247.105 | I11: =C11*0.386102
B12: ='Expanded Table'!C27 | C12: ='Expanded Table'!E27 | D12: ='Expanded Table'!E28 | E12: =C12/C$13 | F12: =D12/D$13 | G12: =IF(D12>0,C12/D12,0) | H12: =C12*247.105 | I12: =C12*0.386102
B13: Total Waterbodies | C13: =SUM(C7:C12) | D13: =SUM(D7:D12) | E13: =SUM(E7:E12) | F13: =SUM(F7:F12) | G13: =SUM(G7:G12) | H13: =SUM(H7:H12) | I13: =SUM(I7:I12)

Sheet Climate
A1: Formatted Tables (can be separate tabs in *.xlsx or Google Sheet)
B3: Climate - PRISM - Mean Annual Precipitation
B4: ='Expanded Table'!C3 | C4: ='Expanded Table'!B3
B5: ='Expanded Table'!C2 | C5: ='Expanded Table'!E2
B6: Spatial Summary Statistics: | C6: mm | D6: in
B7: ='Expanded Table'!C48 | C7: ='Expanded Table'!E48 | D7: =C7*0.0393701
B8: ='Expanded Table'!C45 | C8: ='Expanded Table'!E45 | D8: =C8*0.0393701
B9: ='Expanded Table'!C44 | C9: ='Expanded Table'!E44 | D9: =C9*0.0393701

Sheet Morphometric
B3: Morphometric Analyses
B4: ='Expanded Table'!C3 | C4: ='Expanded Table'!B3
B5: ='Expanded Table'!C2 | C5: ='Expanded Table'!E2
B6: ='Expanded Table'!C4 | C6: ='Expanded Table'!E4
B7: ='Expanded Table'!C5 | C7: ='Expanded Table'!E5 | D7: sq km | E7: =C7*247.105 | F7: acres | G7: =C7/2.59 | H7: sq mi
G8: Percent of total
B9: ='Expanded Table'!C8 | C9: ='Expanded Table'!E8 | D9: km | E9: =C9*0.621371 | F9: mi | G9: =C9/C$11
B10: Non Perrenial Stream Length | C10: ='Expanded Table'!E9+'Expanded Table'!E10 | D10: km | E10: =C10*0.621371 | F10: mi | G10: =C10/C$11
B11: ='Expanded Table'!C12 | C11: ='Expanded Table'!E12 | D11: km | E11: =C11*0.621371 | F11: mi | G11: =C11/C$11
B12: ='Expanded Table'!C14
B13: Basin Geometry
B14: ='Expanded Table'!C51 | C14: ='Expanded Table'!E13 | D14: km | E14: =C14*0.621371 | F14: mi | G14: =C14/C$11
B15: ='Expanded Table'!C53 | C15: ='Expanded Table'!E14+'Expanded Table'!E15 | D15: km | E15: =C15*0.621371 | F15: mi | G15: =C15/C$11
B17: Basin Elevation
B18: ='Expanded Table'!C31 | C18: ='Expanded Table'!E31 | D18: m | E18: =3.280841666667*C18 | F18: ft
B19: ='Expanded Table'!C30 | C19: ='Expanded Table'!E30 | D19: m | E19: =3.280841666667*C19 | F19: ft
B20: ='Expanded Table'!C35 | C20: ='Expanded Table'!E35 | D20: m | E20: =3.280841666667*C20 | F20: ft
B21: ='Expanded Table'!C34 | C21: ='Expanded Table'!E34 | D21: m | E21: =3.280841666667*C21 | F21: ft
B23: Slope Analyses
B24: ='Expanded Table'!C38 | C24: ='Expanded Table'!E38 | D24: deg | E24: =(TAN(RADIANS(C24)))*100 | F24: %
B25: ='Expanded Table'!C37 | C25: ='Expanded Table'!E37 | D25: deg | E25: =(TAN(RADIANS(C25)))*100 | F25: %
B26: ='Expanded Table'!C41 | C26: ='Expanded Table'!E41 | D26: deg | E26: =(TAN(RADIANS(C26)))*100 | F26: %
B28: Drainage Densities
B29: ='Expanded Table'!C59 | C29: ='Expanded Table'!E59 | D29: km/sq km
B30: Drainage Density - Non Perrnial | C30: =('Expanded Table'!E9+'Expanded Table'!E10)/'Expanded Table'!E5 | D30: km/sq km
B31: ='Expanded Table'!C62 | C31: ='Expanded Table'!E62 | D31: km/sq km
B33: Morphometrics
B34: ='Expanded Table'!C54 | C34: ='Expanded Table'!E54
B35: ='Expanded Table'!C55 | C35: ='Expanded Table'!E55
B36: ='Expanded Table'!C56 | C36: ='Expanded Table'!E56
B37: ='Expanded Table'!C58 | C37: ='Expanded Table'!E58

Sheet aggregatedata
A1: field_name | B1: value | C1: friendly_name | D1: units
A2: sum_hucareasqkm | B2: 536.09998 | C2: Total Watershed Area | D2: kilometer ** 2
A3: sum_flowlinelengthperennialkm | B3: 295.74786 | C3: Total Perrenial Stream Length | D3: kilometer
A4: sum_flowlinelengthintermittentkm | B4: 75.271065 | C4: Total Intermittent Stream Length | D4: kilometer
A5: sum_flowlinelengthephemeralkm | B5: 491.17477 | C5: Total Ephemeral Stream Length | D5: kilometer
A6: sum_flowlinelengthcanalskm | B6: 21.037935 | C6: Total Canal Length | D6: kilometer
A7: sum_flowlinelengthallkm | B7: 884.97595 | C7: Total Total Stream Length | D7: kilometer
A8: sum_flowlinefeaturecount | B8: 2382 | C8: Total Number of Stream Segments | D8: count
A9: sum_waterbodyareasqkm | B9: 2.2852273 | C9: Total Total Waterbody Area | D9: kilometer ** 2
A10: sum_waterbodyfeaturecount | B10: 793 | C10: Total Total count of Waterbodies | D10: count
A11: sum_waterbodylakespondsareasqkm | B11: 2.2331293 | C11: Total Lake Area | D11: kilometer ** 2
A12: sum_waterbodylakespondsfeaturecount | B12: 788 | C12: Total Waterbodylakespondsfeaturecount
A13: sum_waterbodyreservoirareasqkm | B13: 0.048098151 | C13: Total Reservoir Area | D13: kilometer ** 2
A14: sum_waterbodyreservoirfeaturecount | B14: 4 | C14: Total Waterbodyreservoirfeaturecount
A15: sum_waterbodyestuariesareasqkm | B15: 0 | C15: Total Estuaries Area | D15: kilometer ** 2
A16: sum_waterbodyestuariesfeaturecount | B16: 0 | C16: Total Waterbodyestuariesfeaturecount
A17: sum_waterbodyplayaareasqkm | B17: 0 | C17: Total Playa Area | D17: kilometer ** 2
A18: sum_waterbodyplayafeaturecount | B18: 0 | C18: Total Waterbodyplayafeaturecount
A19: sum_waterbodyswampmarshareasqkm | B19: 0.0040000002 | C19: Total Swamp/Marsh Area | D19: kilometer ** 2
A20: sum_waterbodyswampmarshfeaturecount | B20: 1 | C20: Total Waterbodyswampmarshfeaturecount
A21: sum_waterbodyicesnowareasqkm | B21: 0 | C21: Total Ice/Snow Area | D21: kilometer ** 2
A22: sum_waterbodyicesnowfeaturecount | B22: 0 | C22: Total Waterbodyicesnowfeaturecount
A23: sum_demsum | B23: 14758558720 | C23: Total DEM Spatial Sum of Grid Values | D23: meter
A24: sum_demcount | B24: 6707376 | C24: Total Number of DEM Grid Cells | D24: count
A25: sum_slopesum | B25: 32905382 | C25: Total Slope Spatial Sum of Grid Values | D25: degree
A26: sum_slopecount | B26: 6707376 | C26: Total Number of Slope Grid Cells | D26: count
A27: sum_precipsum | B27: 329077.66 | C27: Total Precipitation Spatial Sum of Grid Values | D27: millimeter
A28: sum_precipcount | B28: 833 | C28: Total Number of Precipitation Grid Cells | D28: count
A29: sum_catchmentlength | B29: 43.942673 | C29: Total Catchment Length | D29: kilometer
A30: sum_catchmentarea | B30: 536.09998 | C30: Total Catchment Area | D30: kilometer ** 2
A31: min_demminimum | B31: 2017.8392 | C31: Minimum DEM Min | D31: meter
A32: min_slopeminimum | B32: 0 | C32: Minimum Slope Min | D32: degree
A33: min_precipminimum | B33: 262.04001 | C33: Minimum Precipitation Spatial Min | D33: millimeter
A34: min_circularityratio | B34: 0.31262648 | C34: Minimum Circularity Ratio | D34: dimensionless
... A40: countdistinct_huc | B40: 1 | C40: Count distinct HUC10 | D40: count
